<?xml version="1.0" encoding="utf-8"?>
<!-- This URDF was automatically created by SolidWorks to URDF Exporter! Originally created by Stephen Brawner (brawner@gmail.com) 
     Commit Version: 1.5.1-0-g916b5db  Build Version: 1.5.7152.31018
     For more information, please see http://wiki.ros.org/sw_urdf_exporter -->
<robot
  name="lbrMed.sldasm">
  <link
    name="LBRMed_base">
    <inertial>
      <origin
        xyz="-0.0018556 4.9506E-08 0.077758"
        rpy="0 0 0" />
      <mass
        value="6.0056" />
      <inertia
        ixx="0.032885"
        ixy="2.9498E-08"
        ixz="-0.00058157"
        iyy="0.033522"
        iyz="-7.2172E-09"
        izz="0.045495" />
    </inertial>
    <visual>
      <origin
        xyz="0 0 0"
        rpy="0 0 0" />
      <geometry>
        <mesh
          filename="package://lbrMed.sldasm/meshes/LBRMed_base.STL" />
      </geometry>
      <material
        name="">
        <color
          rgba="0.13 0.1 0.33 1" />
      </material>
    </visual>
    <collision>
      <origin
        xyz="0 0 0"
        rpy="0 0 0" />
      <geometry>
        <mesh
          filename="package://lbrMed.sldasm/meshes/LBRMed_base.STL" />
      </geometry>
    </collision>
  </link>
  <link
    name="LBRMed_shoulder">
    <inertial>
      <origin
        xyz="-1.0921E-06 -0.033794 0.1277"
        rpy="0 0 0" />
      <mass
        value="4.1086" />
      <inertia
        ixx="0.032982"
        ixy="4.1814E-08"
        ixz="3.7416E-07"
        iyy="0.033274"
        iyz="0.0049257"
        izz="0.012326" />
    </inertial>
    <visual>
      <origin
        xyz="0 0 0"
        rpy="0 0 0" />
      <geometry>
        <mesh
          filename="package://lbrMed.sldasm/meshes/LBRMed_shoulder.STL" />
      </geometry>
      <material
        name="">
        <color
          rgba="0.9 0.9 0.9 1" />
      </material>
    </visual>
    <collision>
      <origin
        xyz="0 0 0"
        rpy="0 0 0" />
      <geometry>
        <mesh
          filename="package://lbrMed.sldasm/meshes/LBRMed_shoulder.STL" />
      </geometry>
    </collision>
  </link>
  <joint
    name="LBRMed_joint1"
    type="revolute">
    <origin
      xyz="0 0 0.1522"
      rpy="0 0 0" />
    <parent
      link="LBRMed_base" />
    <child
      link="LBRMed_shoulder" />
    <axis
      xyz="0 0 -1" />
    <limit
      lower="-3.1416"
      upper="3.1416"
      effort="10"
      velocity="3" />
  </joint>
  <link
    name="LBRMed_lower_arm">
    <inertial>
      <origin
        xyz="0.00013064 -0.07633 0.037544"
        rpy="0 0 0" />
      <mass
        value="4.4185" />
      <inertia
        ixx="0.04286"
        ixy="-4.2906E-05"
        ixz="-2.4964E-05"
        iyy="0.012833"
        iyz="-0.0077921"
        izz="0.041927" />
    </inertial>
    <visual>
      <origin
        xyz="0 0 0"
        rpy="0 0 0" />
      <geometry>
        <mesh
          filename="package://lbrMed.sldasm/meshes/LBRMed_lower_arm.STL" />
      </geometry>
      <material
        name="">
        <color
          rgba="0.9 0.9 0.9 1" />
      </material>
    </visual>
    <collision>
      <origin
        xyz="0 0 0"
        rpy="0 0 0" />
      <geometry>
        <mesh
          filename="package://lbrMed.sldasm/meshes/LBRMed_lower_arm.STL" />
      </geometry>
    </collision>
  </link>
  <joint
    name="LBRMed_joint2"
    type="revolute">
    <origin
      xyz="0 0 0.2078"
      rpy="-1.5708 0 0" />
    <parent
      link="LBRMed_shoulder" />
    <child
      link="LBRMed_lower_arm" />
    <axis
      xyz="0 0 -1" />
    <limit
      lower="-3.1416"
      upper="3.1416"
      effort="10"
      velocity="3" />
  </joint>
  <link
    name="LBRMed_elbow">
    <inertial>
      <origin
        xyz="1.8351E-06 0.034909 0.11381"
        rpy="0 0 0" />
      <mass
        value="2.6884" />
      <inertia
        ixx="0.016871"
        ixy="9.3037E-08"
        ixz="-1.4954E-07"
        iyy="0.016102"
        iyz="-0.0029863"
        izz="0.005981" />
    </inertial>
    <visual>
      <origin
        xyz="0 0 0"
        rpy="0 0 0" />
      <geometry>
        <mesh
          filename="package://lbrMed.sldasm/meshes/LBRMed_elbow.STL" />
      </geometry>
      <material
        name="">
        <color
          rgba="0.9 0.9 0.9 1" />
      </material>
    </visual>
    <collision>
      <origin
        xyz="0 0 0"
        rpy="0 0 0" />
      <geometry>
        <mesh
          filename="package://lbrMed.sldasm/meshes/LBRMed_elbow.STL" />
      </geometry>
    </collision>
  </link>
  <joint
    name="LBRMed_joint3"
    type="revolute">
    <origin
      xyz="0 -0.2373 0"
      rpy="1.5708 0 0" />
    <parent
      link="LBRMed_lower_arm" />
    <child
      link="LBRMed_elbow" />
    <axis
      xyz="0 0 -1" />
    <limit
      lower="-3.1416"
      upper="3.1416"
      effort="10"
      velocity="3" />
  </joint>
  <link
    name="LBRMed_upper_arm">
    <inertial>
      <origin
        xyz="-7.4267E-08 0.086942 0.02979"
        rpy="0 0 0" />
      <mass
        value="3.2026" />
      <inertia
        ixx="0.025176"
        ixy="-7.1194E-09"
        ixz="2.082E-07"
        iyy="0.0076769"
        iyz="0.004677"
        izz="0.023892" />
    </inertial>
    <visual>
      <origin
        xyz="0 0 0"
        rpy="0 0 0" />
      <geometry>
        <mesh
          filename="package://lbrMed.sldasm/meshes/LBRMed_upper_arm.STL" />
      </geometry>
      <material
        name="">
        <color
          rgba="0.9 0.9 0.9 1" />
      </material>
    </visual>
    <collision>
      <origin
        xyz="0 0 0"
        rpy="0 0 0" />
      <geometry>
        <mesh
          filename="package://lbrMed.sldasm/meshes/LBRMed_upper_arm.STL" />
      </geometry>
    </collision>
  </link>
  <joint
    name="LBRMed_joint4"
    type="revolute">
    <origin
      xyz="0 0.0005 0.1827"
      rpy="1.5708 0 0" />
    <parent
      link="LBRMed_elbow" />
    <child
      link="LBRMed_upper_arm" />
    <axis
      xyz="0 0 -1" />
    <limit
      lower="-3.1416"
      upper="3.1416"
      effort="10"
      velocity="3" />
  </joint>
  <link
    name="LBRMed_wrist1">
    <inertial>
      <origin
        xyz="9.5301E-07 -0.029822 0.066966"
        rpy="0 0 0" />
      <mass
        value="1.2146" />
      <inertia
        ixx="0.0067395"
        ixy="2.5624E-08"
        ixz="8.1717E-09"
        iyy="0.0056681"
        iyz="0.0022283"
        izz="0.0030564" />
    </inertial>
    <visual>
      <origin
        xyz="0 0 0"
        rpy="0 0 0" />
      <geometry>
        <mesh
          filename="package://lbrMed.sldasm/meshes/LBRMed_wrist1.STL" />
      </geometry>
      <material
        name="">
        <color
          rgba="0.9 0.9 0.9 1" />
      </material>
    </visual>
    <collision>
      <origin
        xyz="0 0 0"
        rpy="0 0 0" />
      <geometry>
        <mesh
          filename="package://lbrMed.sldasm/meshes/LBRMed_wrist1.STL" />
      </geometry>
    </collision>
  </link>
  <joint
    name="LBRMed_joint5"
    type="revolute">
    <origin
      xyz="0 0.2168 0.0005"
      rpy="-1.5708 0 0" />
    <parent
      link="LBRMed_upper_arm" />
    <child
      link="LBRMed_wrist1" />
    <axis
      xyz="0 0 -1" />
    <limit
      lower="-3.1416"
      upper="3.1416"
      effort="10"
      velocity="3" />
  </joint>
  <link
    name="LBRMed_wrist2">
    <inertial>
      <origin
        xyz="1.7505E-06 -0.0049557 0.061029"
        rpy="0 0 0" />
      <mass
        value="1.9087" />
      <inertia
        ixx="0.0056122"
        ixy="-3.928E-08"
        ixz="4.0496E-07"
        iyy="0.0036753"
        iyz="-0.00024707"
        izz="0.0054041" />
    </inertial>
    <visual>
      <origin
        xyz="0 0 0"
        rpy="0 0 0" />
      <geometry>
        <mesh
          filename="package://lbrMed.sldasm/meshes/LBRMed_wrist2.STL" />
      </geometry>
      <material
        name="">
        <color
          rgba="0.9 0.9 0.9 1" />
      </material>
    </visual>
    <collision>
      <origin
        xyz="0 0 0"
        rpy="0 0 0" />
      <geometry>
        <mesh
          filename="package://lbrMed.sldasm/meshes/LBRMed_wrist2.STL" />
      </geometry>
    </collision>
  </link>
  <joint
    name="LBRMed_joint6"
    type="revolute">
    <origin
      xyz="0 -0.0607 0.1832"
      rpy="-1.5708 0 0" />
    <parent
      link="LBRMed_wrist1" />
    <child
      link="LBRMed_wrist2" />
    <axis
      xyz="0 0 -1" />
    <limit
      lower="-3.1416"
      upper="3.1416"
      effort="10"
      velocity="3.1416" />
  </joint>
  <link
    name="LBRMed_wrist3">
    <inertial>
      <origin
        xyz="-3.0531E-05 -2.9893E-05 0.013782"
        rpy="0 0 0" />
      <mass
        value="0.20609" />
      <inertia
        ixx="0.00013586"
        ixy="1.4059E-08"
        ixz="-6.6731E-09"
        iyy="0.00013585"
        iyz="2.2202E-09"
        izz="0.00023745" />
    </inertial>
    <visual>
      <origin
        xyz="0 0 0"
        rpy="0 0 0" />
      <geometry>
        <mesh
          filename="package://lbrMed.sldasm/meshes/LBRMed_wrist3.STL" />
      </geometry>
      <material
        name="">
        <color
          rgba="0.05 0.63 0.25 1" />
      </material>
    </visual>
    <collision>
      <origin
        xyz="0 0 0"
        rpy="0 0 0" />
      <geometry>
        <mesh
          filename="package://lbrMed.sldasm/meshes/LBRMed_wrist3.STL" />
      </geometry>
    </collision>
  </link>
  <joint
    name="LBRMed_joint7"
    type="revolute">
    <origin
      xyz="3.3739E-05 -0.091 0.060728"
      rpy="1.5708 0 0" />
    <parent
      link="LBRMed_wrist2" />
    <child
      link="LBRMed_wrist3" />
    <axis
      xyz="0 0 -1" />
    <limit
      lower="-3.1416"
      upper="3.1416"
      effort="10"
      velocity="3" />
  </joint>
</robot>